Workbook
Name SegmentaciónDeDatos_Ex_date_Efectos1: #N/A
Name SegmentaciónDeDatos_Ex_date_Efectos11: #N/A
Name SegmentaciónDeDatos_Tipo_Valor__Mexico: #N/A

Sheet Posición
A1: Posición | B1: Portfolio | C1: Tipo Valor (Mexico) | D1: Ex date/Efectos | E1: Fecha Registro | F1: Fecha Pago | G1: Tipo de derecho | H1: Estatus | I1: Proporción/importe | J1: Pos Dividendo | K1: ISIN | L1: =TODAY() -> 46230
A2: =IF(H2="APLICADO","SI","NO") -> NO | B2: =Covaf!B2 -> AXAIM29 | C2: =CONCATENATE(Covaf!E2,"_",Covaf!F2,"_",Covaf!G2) -> I_BANOBRA_26295 | D2: =IFERROR(VLOOKUP(C2,BIVA!$C$3:$J$5311,3,0),"") | E2: =IFERROR(VLOOKUP(C2,BIVA!$C$3:$J$5311,4,0),"") | F2: =IFERROR(VLOOKUP(C2,BIVA!$C$3:$J$5311,5,0),"") | G2: =IFERROR(VLOOKUP(C2,BIVA!$C$3:$J$5311,6,0),"") | H2: =IFERROR(VLOOKUP(C2,BIVA!$C$3:$J$5311,7,0),"") | I2: =IFERROR(VLOOKUP(C2,BIVA!$C$3:$J$5311,8,0),"") | J2: =Covaf!H2 -> 199956 | K2: =Covaf!X2 -> MX0IBA064X15
A3: =IF(H3="APLICADO","SI","NO") -> NO | B3: =Covaf!B3 -> AXAIM29 | C3: =CONCATENATE(Covaf!E3,"_",Covaf!F3,"_",Covaf!G3) -> M_BONOS_270603 | D3: =IFERROR(VLOOKUP(C3,BIVA!$C$3:$J$5311,3,0),"") | E3: =IFERROR(VLOOKUP(C3,BIVA!$C$3:$J$5311,4,0),"") | F3: =IFERROR(VLOOKUP(C3,BIVA!$C$3:$J$5311,5,0),"") | G3: =IFERROR(VLOOKUP(C3,BIVA!$C$3:$J$5311,6,0),"") | H3: =IFERROR(VLOOKUP(C3,BIVA!$C$3:$J$5311,7,0),"") | I3: =IFERROR(VLOOKUP(C3,BIVA!$C$3:$J$5311,8,0),"") | J3: =Covaf!H3 -> 8800 | K3: =Covaf!X3 -> MX0MGO0000D8
A4: =IF(H4="APLICADO","SI","NO") -> NO | B4: =Covaf!B4 -> AXAIM29 | C4: =CONCATENATE(Covaf!E4,"_",Covaf!F4,"_",Covaf!G4) -> S_UDIBONO_261203 | D4: =IFERROR(VLOOKUP(C4,BIVA!$C$3:$J$5311,3,0),"") | E4: =IFERROR(VLOOKUP(C4,BIVA!$C$3:$J$5311,4,0),"") | F4: =IFERROR(VLOOKUP(C4,BIVA!$C$3:$J$5311,5,0),"") | G4: =IFERROR(VLOOKUP(C4,BIVA!$C$3:$J$5311,6,0),"") | H4: =IFERROR(VLOOKUP(C4,BIVA!$C$3:$J$5311,7,0),"") | I4: =IFERROR(VLOOKUP(C4,BIVA!$C$3:$J$5311,8,0),"") | J4: =Covaf!H4 -> 127 | K4: =Covaf!X4 -> MX0SGO0000M6
A5: =IF(H5="APLICADO","SI","NO") -> NO | B5: =Covaf!B5 -> AXAIM29 | C5: =CONCATENATE(Covaf!E5,"_",Covaf!F5,"_",Covaf!G5) -> 1I_VT_* | D5: =IFERROR(VLOOKUP(C5,BIVA!$C$3:$J$5311,3,0),"") | E5: =IFERROR(VLOOKUP(C5,BIVA!$C$3:$J$5311,4,0),"") | F5: =IFERROR(VLOOKUP(C5,BIVA!$C$3:$J$5311,5,0),"") | G5: =IFERROR(VLOOKUP(C5,BIVA!$C$3:$J$5311,6,0),"") | H5: =IFERROR(VLOOKUP(C5,BIVA!$C$3:$J$5311,7,0),"") | I5: =IFERROR(VLOOKUP(C5,BIVA!$C$3:$J$5311,8,0),"") | J5: =Covaf!H5 -> 146 | K5: =Covaf!X5 -> US9220427424
A6: =IF(H6="APLICADO","SI","NO") -> NO | B6: =Covaf!B6 -> AXAIM41 | C6: =CONCATENATE(Covaf!E6,"_",Covaf!F6,"_",Covaf!G6) -> I_BANOBRA_26295 | D6: =IFERROR(VLOOKUP(C6,BIVA!$C$3:$J$5311,3,0),"") | E6: =IFERROR(VLOOKUP(C6,BIVA!$C$3:$J$5311,4,0),"") | F6: =IFERROR(VLOOKUP(C6,BIVA!$C$3:$J$5311,5,0),"") | G6: =IFERROR(VLOOKUP(C6,BIVA!$C$3:$J$5311,6,0),"") | H6: =IFERROR(VLOOKUP(C6,BIVA!$C$3:$J$5311,7,0),"") | I6: =IFERROR(VLOOKUP(C6,BIVA!$C$3:$J$5311,8,0),"") | J6: =Covaf!H6 -> 251674 | K6: =Covaf!X6 -> MX0IBA064X15
A7: =IF(H7="APLICADO","SI","NO") -> NO | B7: =Covaf!B7 -> AXAIM41 | C7: =CONCATENATE(Covaf!E7,"_",Covaf!F7,"_",Covaf!G7) -> M_BONOS_290531 | D7: =IFERROR(VLOOKUP(C7,BIVA!$C$3:$J$5311,3,0),"") | E7: =IFERROR(VLOOKUP(C7,BIVA!$C$3:$J$5311,4,0),"") | F7: =IFERROR(VLOOKUP(C7,BIVA!$C$3:$J$5311,5,0),"") | G7: =IFERROR(VLOOKUP(C7,BIVA!$C$3:$J$5311,6,0),"") | H7: =IFERROR(VLOOKUP(C7,BIVA!$C$3:$J$5311,7,0),"") | I7: =IFERROR(VLOOKUP(C7,BIVA!$C$3:$J$5311,8,0),"") | J7: =Covaf!H7 -> 7300 | K7: =Covaf!X7 -> MX0MGO0000H9
A8: =IF(H8="APLICADO","SI","NO") -> NO | B8: =Covaf!B8 -> AXAIM41 | C8: =CONCATENATE(Covaf!E8,"_",Covaf!F8,"_",Covaf!G8) -> S_UDIBONO_261203 | D8: =IFERROR(VLOOKUP(C8,BIVA!$C$3:$J$5311,3,0),"") | E8: =IFERROR(VLOOKUP(C8,BIVA!$C$3:$J$5311,4,0),"") | F8: =IFERROR(VLOOKUP(C8,BIVA!$C$3:$J$5311,5,0),"") | G8: =IFERROR(VLOOKUP(C8,BIVA!$C$3:$J$5311,6,0),"") | H8: =IFERROR(VLOOKUP(C8,BIVA!$C$3:$J$5311,7,0),"") | I8: =IFERROR(VLOOKUP(C8,BIVA!$C$3:$J$5311,8,0),"") | J8: =Covaf!H8 -> 174 | K8: =Covaf!X8 -> MX0SGO0000M6
A9: =IF(H9="APLICADO","SI","NO") -> NO | B9: =Covaf!B9 -> AXAIM41 | C9: =CONCATENATE(Covaf!E9,"_",Covaf!F9,"_",Covaf!G9) -> 1I_VT_* | D9: =IFERROR(VLOOKUP(C9,BIVA!$C$3:$J$5311,3,0),"") | E9: =IFERROR(VLOOKUP(C9,BIVA!$C$3:$J$5311,4,0),"") | F9: =IFERROR(VLOOKUP(C9,BIVA!$C$3:$J$5311,5,0),"") | G9: =IFERROR(VLOOKUP(C9,BIVA!$C$3:$J$5311,6,0),"") | H9: =IFERROR(VLOOKUP(C9,BIVA!$C$3:$J$5311,7,0),"") | I9: =IFERROR(VLOOKUP(C9,BIVA!$C$3:$J$5311,8,0),"") | J9: =Covaf!H9 -> 203 | K9: =Covaf!X9 -> US9220427424
A10: =IF(H10="APLICADO","SI","NO") -> NO | B10: =Covaf!B10 -> AXAIM53 | C10: =CONCATENATE(Covaf!E10,"_",Covaf!F10,"_",Covaf!G10) -> I_BANOBRA_26295 | D10: =IFERROR(VLOOKUP(C10,BIVA!$C$3:$J$5311,3,0),"") | E10: =IFERROR(VLOOKUP(C10,BIVA!$C$3:$J$5311,4,0),"") | F10: =IFERROR(VLOOKUP(C10,BIVA!$C$3:$J$5311,5,0),"") | G10: =IFERROR(VLOOKUP(C10,BIVA!$C$3:$J$5311,6,0),"") | H10: =IFERROR(VLOOKUP(C10,BIVA!$C$3:$J$5311,7,0),"") | I10: =IFERROR(VLOOKUP(C10,BIVA!$C$3:$J$5311,8,0),"") | J10: =Covaf!H10 -> 234586 | K10: =Covaf!X10 -> MX0IBA064X15
A11: =IF(H11="APLICADO","SI","NO") -> NO | B11: =Covaf!B11 -> AXAIM53 | C11: =CONCATENATE(Covaf!E11,"_",Covaf!F11,"_",Covaf!G11) -> M_BONOS_290531 | D11: =IFERROR(VLOOKUP(C11,BIVA!$C$3:$J$5311,3,0),"") | E11: =IFERROR(VLOOKUP(C11,BIVA!$C$3:$J$5311,4,0),"") | F11: =IFERROR(VLOOKUP(C11,BIVA!$C$3:$J$5311,5,0),"") | G11: =IFERROR(VLOOKUP(C11,BIVA!$C$3:$J$5311,6,0),"") | H11: =IFERROR(VLOOKUP(C11,BIVA!$C$3:$J$5311,7,0),"") | I11: =IFERROR(VLOOKUP(C11,BIVA!$C$3:$J$5311,8,0),"") | J11: =Covaf!H11 -> 5600 | K11: =Covaf!X11 -> MX0MGO0000H9
A12: =IF(H12="APLICADO","SI","NO") -> NO | B12: =Covaf!B12 -> AXAIM53 | C12: =CONCATENATE(Covaf!E12,"_",Covaf!F12,"_",Covaf!G12) -> S_UDIBONO_261203 | D12: =IFERROR(VLOOKUP(C12,BIVA!$C$3:$J$5311,3,0),"") | E12: =IFERROR(VLOOKUP(C12,BIVA!$C$3:$J$5311,4,0),"") | F12: =IFERROR(VLOOKUP(C12,BIVA!$C$3:$J$5311,5,0),"") | G12: =IFERROR(VLOOKUP(C12,BIVA!$C$3:$J$5311,6,0),"") | H12: =IFERROR(VLOOKUP(C12,BIVA!$C$3:$J$5311,7,0),"") | I12: =IFERROR(VLOOKUP(C12,BIVA!$C$3:$J$5311,8,0),"") | J12: =Covaf!H12 -> 183 | K12: =Covaf!X12 -> MX0SGO0000M6
A13: =IF(H13="APLICADO","SI","NO") -> NO | B13: =Covaf!B13 -> AXAIM53 | C13: =CONCATENATE(Covaf!E13,"_",Covaf!F13,"_",Covaf!G13) -> 1I_VT_* | D13: =IFERROR(VLOOKUP(C13,BIVA!$C$3:$J$5311,3,0),"") | E13: =IFERROR(VLOOKUP(C13,BIVA!$C$3:$J$5311,4,0),"") | F13: =IFERROR(VLOOKUP(C13,BIVA!$C$3:$J$5311,5,0),"") | G13: =IFERROR(VLOOKUP(C13,BIVA!$C$3:$J$5311,6,0),"") | H13: =IFERROR(VLOOKUP(C13,BIVA!$C$3:$J$5311,7,0),"") | I13: =IFERROR(VLOOKUP(C13,BIVA!$C$3:$J$5311,8,0),"") | J13: =Covaf!H13 -> 244 | K13: =Covaf!X13 -> US9220427424
... A5576: =IF(H5576="APLICADO","SI","NO") -> NO | B5576: =Covaf!B5576 -> 0 | C5576: =CONCATENATE(Covaf!E5576,"_",Covaf!F5576,"_",Covaf!G5576) -> __ | D5576: =IFERROR(VLOOKUP(C5576,BIVA!$C$3:$J$5311,3,0),"") | E5576: =IFERROR(VLOOKUP(C5576,BIVA!$C$3:$J$5311,4,0),"") | F5576: =IFERROR(VLOOKUP(C5576,BIVA!$C$3:$J$5311,5,0),"") | G5576: =IFERROR(VLOOKUP(C5576,BIVA!$C$3:$J$5311,6,0),"") | H5576: =IFERROR(VLOOKUP(C5576,BIVA!$C$3:$J$5311,7,0),"") | I5576: =IFERROR(VLOOKUP(C5576,BIVA!$C$3:$J$5311,8,0),"") | J5576: =Covaf!H5576 -> 0 | K5576: =Covaf!X5576 -> 0

Sheet BIVA
A1: Clave | B1: Serie | C1: Emisión | D1: ISIN | E1: Ex date/Efectos | F1: Registro | G1: Pago | H1: Tipo de derecho | I1: Estatus | J1: Proporción/importe | K1: Moneda | L1: Importe
A2: CATMRCK | B2: 17 | C2: 1R_CATMRCK_17 | D2: MX1RCA260007 | E2: 24/07/2026 | F2: 24/07/2026 | G2: 27/07/2026 | H2: Distribución en efectivo | I2: Aplicado | J2: 0.25157955097 MXN | K2: MXN | L2: $0.25157955097 | M2: 378,286,039
A3: FVIA | B3: 16 | C3: FF_FVIA_16,17 | D3: MXFFFV000007 | E3: 24/07/2026 | F3: 24/07/2026 | G3: 27/07/2026 | H3: Distribución en efectivo | I3: Aplicado | J3: SERIE(S) '16' CUPON VIGENTE 0 CUPON PAGO 0 A MXN $ 0.3889785940707460 | K3: MXN | L3: $0.388978594070746
A4: LIVCK | B4: 15 | C4: 1R_LIVCK_15 | D4: MX1RLI0A0002 | E4: 24/07/2026 | F4: 24/07/2026 | G4: 27/07/2026 | H4: Reembolso | I4: Aplicado | J4: 0.014759274420067 MXN | K4: MXN | L4: $0.014759274420067 | M4: 8,450,279,902
A5: NXXMFCK | B5: 18 | C5: 1R_NXXMFCK_18 | D5: MX1RNX000007 | E5: 24/07/2026 | F5: 24/07/2026 | G5: 27/07/2026 | H5: Reembolso | I5: Aplicado | J5: 6.83848666802134 MXN | K5: MXN | L5: $6.83848666802134 | M5: 7,165,328
A6: FFLA4CK | B6: 15 | C6: 1R_FFLA4CK_15 | D6: MX1RFF040005 | E6: 27/07/2026 | F6: 27/07/2026 | G6: 28/07/2026 | H6: Reembolso | I6: Aplicado | J6: 6.3733224950393 MXN | K6: MXN | L6: $6.3733224950393 | M6: 1,114,259
A7: LOCK3PI | B7: 21 | C7: 1R_LOCK3PI_21 | D7: MX1RLO060004 | E7: 27/07/2026 | F7: 27/07/2026 | G7: 28/07/2026 | H7: Reembolso | I7: Aplicado | J7: 0.328504508778 USD | K7: USD | L7: $0.328504508778 | M7: 657,717
A8: LOCK3PI | B8: 21-2 | C8: 1R_LOCK3PI_21-2 | D8: MX1RLO060012 | E8: 27/07/2026 | F8: 27/07/2026 | G8: 28/07/2026 | H8: Reembolso | I8: Aplicado | J8: 0.3035633701322 USD | K8: USD | L8: $0.3035633701322 | M8: 3,089,042
A9: PLA2CK | B9: 17 | C9: 1R_PLA2CK_17 | D9: MX1RPL0Q0009 | E9: 27/07/2026 | F9: 27/07/2026 | G9: 28/07/2026 | H9: Distribución en efectivo | I9: Aplicado | J9: SERIE(S) '17' CUPON VIGENTE 0 CUPON PAGO 0 A MXN $ 0.098587880568 | K9: MXN | L9: $0.098587880568
A10: FANVIPI | B10: 23 | C10: 1R_FANVIPI_23 | D10: MX1RFA0E0007 | E10: 24/07/2026 | F10: 24/07/2026 | G10: 29/07/2026 | H10: Suscripción | I10: Aplicado | J10: 1 Actuales X 0.1051768540502 Nuevos a 100 USD | K10: USD | N10: $100 | O10: 104,550
A11: CAPI | B11: 22-2 | C11: 1R_CAPI_22-2 | D11: MX1RCA210010 | E11: 27/07/2026 | F11: 27/07/2026 | G11: 30/07/2026 | H11: Suscripción | I11: Aplicado | J11: 1 Actuales X 0.0015452605971 Nuevos a 100 USD | K11: USD | N11: $100 | O11: 1,621
A12: CAPI | B12: 22-3 | C12: 1R_CAPI_22-3 | D12: MX1RCA210028 | E12: 27/07/2026 | F12: 27/07/2026 | G12: 30/07/2026 | H12: Suscripción | I12: Aplicado | J12: 1 Actuales X 0.001380232281 Nuevos a 100 USD | K12: USD | N12: $100 | O12: 1,621
A13: CAPI | B13: 23-4 | C13: 1R_CAPI_23-4 | D13: MX1RCA210069 | E13: 27/07/2026 | F13: 27/07/2026 | G13: 30/07/2026 | H13: Suscripción | I13: Aplicado | J13: 1 Actuales X 0.006137568561 Nuevos a 100 USD | K13: USD | N13: $100 | O13: 5,360
A14: CAPI | B14: 23-5 | C14: 1R_CAPI_23-5 | D14: MX1RCA210077 | E14: 27/07/2026 | F14: 27/07/2026 | G14: 30/07/2026 | H14: Suscripción | I14: Aplicado | J14: 1 Actuales X 0.0061713999693 Nuevos a 100 USD | K14: USD | N14: $100 | O14: 5,425
A15: CAPI | B15: 23-6 | C15: 1R_CAPI_23-6 | D15: MX1RCA210085 | E15: 27/07/2026 | F15: 27/07/2026 | G15: 30/07/2026 | H15: Suscripción | I15: Aplicado | J15: 1 Actuales X 0.0062123821652 Nuevos a 100 USD | K15: USD | N15: $100 | O15: 5,425
A16: GLOB1PI | B16: 22-17 | C16: 1R_GLOB1PI_22-17 | D16: MX1RGL0300G8 | E16: 27/07/2026 | F16: 27/07/2026 | G16: 30/07/2026 | H16: Suscripción | I16: Aplicado | J16: 1 Actuales X 0.0147286821706 Nuevos a 100 USD | K16: USD | N16: $100 | O16: 4,503
A17: GLOB1PI | B17: 22-18 | C17: 1R_GLOB1PI_22-18 | D17: MX1RGL0300H6 | E17: 27/07/2026 | F17: 27/07/2026 | G17: 30/07/2026 | H17: Suscripción | I17: Aplicado | J17: 1 Actuales X 0.0125531314946 Nuevos a 100 USD | K17: USD | N17: $100 | O17: 6,010
A18: GLOB1PI | B18: 22-19 | C18: 1R_GLOB1PI_22-19 | D18: MX1RGL0300I4 | E18: 27/07/2026 | F18: 27/07/2026 | G18: 30/07/2026 | H18: Suscripción | I18: Aplicado | J18: 1 Actuales X 0.012449947483 Nuevos a 100 USD | K18: USD | N18: $100 | O18: 6,946
A19: GLOB1PI | B19: 22-20 | C19: 1R_GLOB1PI_22-20 | D19: MX1RGL0300J2 | E19: 27/07/2026 | F19: 27/07/2026 | G19: 30/07/2026 | H19: Suscripción | I19: Aplicado | J19: 1 Actuales X 0.0122696128842 Nuevos a 100 USD | K19: USD | N19: $100 | O19: 6,932
A20: GLOB1PI | B20: 22-21 | C20: 1R_GLOB1PI_22-21 | D20: MX1RGL0300K0 | E20: 27/07/2026 | F20: 27/07/2026 | G20: 30/07/2026 | H20: Suscripción | I20: Aplicado | J20: 1 Actuales X 0.0121254795168 Nuevos a 100 USD | K20: USD | N20: $100 | O20: 7,801
A21: GLOB1PI | B21: 22-22 | C21: 1R_GLOB1PI_22-22 | D21: MX1RGL0300L8 | E21: 27/07/2026 | F21: 27/07/2026 | G21: 30/07/2026 | H21: Suscripción | I21: Aplicado | J21: 1 Actuales X 0.0117956493118 Nuevos a 100 USD | K21: USD | N21: $100 | O21: 7,920
... A24: KANANPI | B24: 24-G | C24: 1R_KANANPI_24-G | D24: MX1RKA000080 | E24: 27/07/2026 | F24: 27/07/2026 | G24: 30/07/2026 | H24: Suscripción | I24: Aplicado | J24: 1 Actuales X 0.970783860553 Nuevos a 100 USD | K24: USD | N24: $100 | O24: 220,100
A25: COST | B25: * | C25: 1A_COST_* | D25: US22160K1051 | E25: 24/07/2026 | F25: 24/07/2026 | G25: 07/08/2026 | H25: Dividendo en efectivo | I25: Aplicado | J25: Option Number: "001" Option Type: "Cash" Default Option: "Yes" Gross Dividend Rate: "1.47 USD" Option Number: "002" Option Type: "Security" Default Option: "No"
A26: DX2X | B26: N | C26: 1I_DX2X_N | D26: LU0328475792 | E26: 24/07/2026 | H26: Otro | I26: Informativo
A27: GEHC | B27: * | C27: 1A_GEHC_* | D27: US36266G1076 | E27: 24/07/2026 | F27: 24/07/2026 | G27: 14/08/2026 | H27: Dividendo en efectivo | I27: Aplicado | J27: Option Number: "001" Option Type: "Cash" Default Option: "Yes" Gross Dividend Rate: "0.035 USD" Option Number: "002" Option Type: "Security" Default Option: "No"
A28: KPN | B28: N | C28: 1A_KPN_N | D28: NL0000009082 | E28: 24/07/2026 | F28: 27/07/2026 | G28: 03/08/2026 | H28: Dividendo en efectivo | I28: Aplicado | J28: Option Number: "001" Option Type: "Cash" Default Option: "Yes" Gross Dividend Rate: "0.08 EUR" Net Dividend Rate: "0.068 EUR"
A29: PFE | B29: * | C29: 1A_PFE_* | D29: US7170811035 | E29: 24/07/2026 | F29: 24/07/2026 | G29: 01/09/2026 | H29: Dividendo en efectivo | I29: Aplicado | J29: Option Number: "001" Option Type: "Cash" Default Option: "Yes" Gross Dividend Rate: "0.43 USD" Option Number: "002" Option Type: "Security" Default Option: "No"
A30: PG | B30: * | C30: 1A_PG_* | D30: US7427181091 | E30: 24/07/2026 | F30: 24/07/2026 | G30: 17/08/2026 | H30: Dividendo en efectivo | I30: Aplicado | J30: Option Number: "001" Option Type: "Cash" Default Option: "Yes" Gross Dividend Rate: "1.0885 USD" Option Number: "002" Option Type: "Security" Default Option: "No"
A31: PNR | B31: N | C31: 1A_PNR_N | D31: IE00BLS09M33 | E31: 24/07/2026 | F31: 24/07/2026 | G31: 07/08/2026 | H31: Dividendo en efectivo | I31: Aplicado | J31: Option Number: "001" Option Type: "Cash" Default Option: "Yes" Gross Dividend Rate: "0.27 USD"
A32: TMHC | B32: * | C32: 1A_TMHC_* | D32: US87724P1066 | E32: 24/07/2026 | H32: Fusión | I32: Aplicado | J32: Option Number: "001" Option Type: "Cash" Default Option: "Yes" Generic Cash Price Received Per Product: "72.5 USD" - "1.0" Unit
A33: ASML | B33: N | C33: 1A_ASML_N | D33: NL0010273215 | E33: 27/07/2026 | F33: 28/07/2026 | G33: 05/08/2026 | H33: Dividendo en efectivo | I33: Aplicado | J33: Option Number: "001" Option Type: "Cash" Default Option: "Yes" Gross Dividend Rate: "1.88 EUR" Net Dividend Rate: "1.598 EUR"
A34: BNY | B34: * | C34: 1A_BNY_* | D34: US0640581007 | E34: 27/07/2026 | F34: 27/07/2026 | G34: 07/08/2026 | H34: Dividendo en efectivo | I34: Aplicado | J34: Option Number: "001" Option Type: "Cash" Default Option: "Yes" Gross Dividend Rate: "0.63 USD" Option Number: "002" Option Type: "Security" Default Option: "No"
A35: NOKIA | B35: N | C35: 1A_NOKIA_N | D35: FI0009000681 | E35: 27/07/2026 | F35: 28/07/2026 | G35: 06/08/2026 | H35: Dividendo en efectivo | I35: Aplicado | J35: Option Number: "001" Option Type: "Cash" Default Option: "Yes" Gross Dividend Rate: "0.04 EUR" Net Dividend Rate: "0.026 EUR"
A36: QBTS | B36: * | C36: 1A_QBTS_* | D36: US26740W1099 | E36: 27/07/2026 | H36: Canje simple | I36: Aplicado
A37: RY | B37: N | C37: 1A_RY_N | D37: CA7800871021 | E37: 27/07/2026 | F37: 27/07/2026 | G37: 24/08/2026 | H37: Dividendo en efectivo | I37: Aplicado | J37: Option Number: "001" Option Type: "Cash" Default Option: "Yes" Gross Dividend Rate: "1.76 CAD" Net Dividend Rate: "1.32 CAD"
A38: WIT | B38: N | C38: 1A_WIT_N | D38: US97651M1099 | E38: 27/07/2026 | F38: 27/07/2026 | H38: Dividendo en efectivo | I38: Aplicado | J38: Option Number: "001" Option Type: "Cash" Default Option: "Yes" Gross Dividend Rate: "0.020775 USD" Net Dividend Rate: "0.018507 USD" Option Number: "002" Option Type: "Security" Default Option: "No"

Sheet Covaf
B1: CVE_FONDO | C1: FECHA | D1: CVE_TEN | E1: CVE_BMV | F1: EMISORA | G1: SERIE | H1: TIT_FDIA | I1: CTO_FDIA | J1: PRECIO | K1: IMP_MDO | L1: DIAS_UH | M1: DIAS_EQ | N1: TASA_POND | O1: TASA_EQ | P1: FINICIO | Q1: FVENCE | R1: DIAS_CPN | S1: ACT_TOT | T1: ACT_NET | U1: EMISOR | V1: CLS_FONDO | W1: ACT_BASE | X1: ISIN | Y1: BURSATIL_CALIFIC
B2: AXAIM29 | C2: 23/07/2026 | D2: D | E2: I | F2: BANOBRA | G2: 26295 | H2: 199956 | I2: 1 | J2: 1 | K2: 199956 | L2: 0 | M2: 0 | N2: 0 | O2: 0 | P2: 25/06/2026 | Q2: 24/07/2026 | R2: 0 | S2: 1601532.5 | T2: 1600949.7 | U2: BANOBRA | V2: RVDIS | W2: 1601532.5 | X2: MX0IBA064X15 | Y2: mxA-1+
B3: AXAIM29 | C3: 23/07/2026 | D3: D | E3: M | F3: BONOS | G3: 270603 | H3: 8800 | I3: 101.03 | J3: 101.63723 | K3: 894407.6 | L3: 314 | M3: 0 | N3: 7.5 | O3: 0 | P3: 28/12/2006 | Q3: 03/06/2027 | R3: 132 | S3: 1601532.5 | T3: 1600949.7 | U3: GOBMEX | V3: RVDIS | W3: 1601532.5 | X3: MX0MGO0000D8 | Y3: HR AAA
B4: AXAIM29 | C4: 23/07/2026 | D4: D | E4: S | F4: UDIBONO | G4: 261203 | H4: 127 | I4: 866.24 | J4: 884.25062 | K4: 112299.83 | L4: 132 | M4: 0 | N4: 3 | O4: 0 | P4: 09/12/2021 | Q4: 03/12/2026 | R4: 132 | S4: 1601532.5 | T4: 1600949.7 | U4: GOBMEX | V4: RVDIS | W4: 1601532.5 | X4: MX0SGO0000M6 | Y4: HR AAA
B5: AXAIM29 | C5: 23/07/2026 | D5: D | E5: 1I | F5: VT | G5: * | H5: 146 | I5: 2540.21 | J5: 2704.5759 | K5: 394868.09 | L5: 0 | M5: 0 | N5: 0 | O5: 0 | P5: 20/10/2009 | R5: 0 | S5: 1601532.5 | T5: 1600949.7 | U5: VT | V5: RVDIS | W5: 1601532.5 | X5: US9220427424 | Y5: N/A
B6: AXAIM41 | C6: 23/07/2026 | D6: D | E6: I | F6: BANOBRA | G6: 26295 | H6: 251674 | I6: 1 | J6: 1 | K6: 251674 | L6: 0 | M6: 0 | N6: 0 | O6: 0 | P6: 25/06/2026 | Q6: 24/07/2026 | R6: 0 | S6: 1700879.4 | T6: 1700353.9 | U6: BANOBRA | V6: RVDIS | W6: 1700829.4 | X6: MX0IBA064X15 | Y6: mxA-1+
B7: AXAIM41 | C7: 23/07/2026 | D7: D | E7: M | F7: BONOS | G7: 290531 | H7: 7300 | I7: 102.16 | J7: 102.22827 | K7: 746266.34 | L7: 1042 | M7: 0 | N7: 8.5 | O7: 0 | P7: 24/12/2008 | Q7: 31/05/2029 | R7: 132 | S7: 1700879.4 | T7: 1700353.9 | U7: GOBMEX | V7: RVDIS | W7: 1700829.4 | X7: MX0MGO0000H9 | Y7: HR AAA
B8: AXAIM41 | C8: 23/07/2026 | D8: D | E8: S | F8: UDIBONO | G8: 261203 | H8: 174 | I8: 866.24 | J8: 884.25062 | K8: 153859.61 | L8: 132 | M8: 0 | N8: 3 | O8: 0 | P8: 09/12/2021 | Q8: 03/12/2026 | R8: 132 | S8: 1700879.4 | T8: 1700353.9 | U8: GOBMEX | V8: RVDIS | W8: 1700829.4 | X8: MX0SGO0000M6 | Y8: HR AAA
B9: AXAIM41 | C9: 23/07/2026 | D9: D | E9: 1I | F9: VT | G9: * | H9: 203 | I9: 2540.21 | J9: 2704.5759 | K9: 549028.92 | L9: 0 | M9: 0 | N9: 0 | O9: 0 | P9: 20/10/2009 | R9: 0 | S9: 1700879.4 | T9: 1700353.9 | U9: VT | V9: RVDIS | W9: 1700829.4 | X9: US9220427424 | Y9: N/A
B10: AXAIM53 | C10: 23/07/2026 | D10: D | E10: I | F10: BANOBRA | G10: 26295 | H10: 234586 | I10: 1 | J10: 1 | K10: 234586 | L10: 0 | M10: 0 | N10: 0 | O10: 0 | P10: 25/06/2026 | Q10: 24/07/2026 | R10: 0 | S10: 1628798.8 | T10: 1628365.2 | U10: BANOBRA | V10: RVDIS | W10: 1628798.8 | X10: MX0IBA064X15 | Y10: mxA-1+
B11: AXAIM53 | C11: 23/07/2026 | D11: D | E11: M | F11: BONOS | G11: 290531 | H11: 5600 | I11: 102.16 | J11: 102.22827 | K11: 572478.29 | L11: 1042 | M11: 0 | N11: 8.5 | O11: 0 | P11: 24/12/2008 | Q11: 31/05/2029 | R11: 132 | S11: 1628798.8 | T11: 1628365.2 | U11: GOBMEX | V11: RVDIS | W11: 1628798.8 | X11: MX0MGO0000H9 | Y11: HR AAA
B12: AXAIM53 | C12: 23/07/2026 | D12: D | E12: S | F12: UDIBONO | G12: 261203 | H12: 183 | I12: 866.24 | J12: 884.25062 | K12: 161817.86 | L12: 132 | M12: 0 | N12: 3 | O12: 0 | P12: 09/12/2021 | Q12: 03/12/2026 | R12: 132 | S12: 1628798.8 | T12: 1628365.2 | U12: GOBMEX | V12: RVDIS | W12: 1628798.8 | X12: MX0SGO0000M6 | Y12: HR AAA
B13: AXAIM53 | C13: 23/07/2026 | D13: D | E13: 1I | F13: VT | G13: * | H13: 244 | I13: 2540.21 | J13: 2704.5759 | K13: 659916.53 | L13: 0 | M13: 0 | N13: 0 | O13: 0 | P13: 20/10/2009 | R13: 0 | S13: 1628798.8 | T13: 1628365.2 | U13: VT | V13: RVDIS | W13: 1628798.8 | X13: US9220427424 | Y13: N/A
B14: AXAIM65 | C14: 23/07/2026 | D14: D | E14: I | F14: BANOBRA | G14: 26295 | H14: 124733 | I14: 1 | J14: 1 | K14: 124733 | L14: 0 | M14: 0 | N14: 0 | O14: 0 | P14: 25/06/2026 | Q14: 24/07/2026 | R14: 0 | S14: 1855876.6 | T14: 1855716.8 | U14: BANOBRA | V14: RVDIS | W14: 1855876.6 | X14: MX0IBA064X15 | Y14: mxA-1+
B15: AXAIM65 | C15: 23/07/2026 | D15: D | E15: M | F15: BONOS | G15: 290531 | H15: 700 | I15: 102.16 | J15: 102.22827 | K15: 71559.79 | L15: 1042 | M15: 0 | N15: 8.5 | O15: 0 | P15: 24/12/2008 | Q15: 31/05/2029 | R15: 132 | S15: 1855876.6 | T15: 1855716.8 | U15: GOBMEX | V15: RVDIS | W15: 1855876.6 | X15: MX0MGO0000H9 | Y15: HR AAA
B16: AXAIM65 | C16: 23/07/2026 | D16: D | E16: S | F16: UDIBONO | G16: 261203 | H16: 216 | I16: 866.24 | J16: 884.25062 | K16: 190998.13 | L16: 132 | M16: 0 | N16: 3 | O16: 0 | P16: 09/12/2021 | Q16: 03/12/2026 | R16: 132 | S16: 1855876.6 | T16: 1855716.8 | U16: GOBMEX | V16: RVDIS | W16: 1855876.6 | X16: MX0SGO0000M6 | Y16: HR AAA
B17: AXAIM65 | C17: 23/07/2026 | D17: D | E17: 1I | F17: VT | G17: * | H17: 543 | I17: 2540.21 | J17: 2704.5759 | K17: 1468584.7 | L17: 0 | M17: 0 | N17: 0 | O17: 0 | P17: 20/10/2009 | R17: 0 | S17: 1855876.6 | T17: 1855716.8 | U17: VT | V17: RVDIS | W17: 1855876.6 | X17: US9220427424 | Y17: N/A
B18: DEUDAOP | C18: 23/07/2026 | D18: D | E18: BI | F18: CETES | G18: 280412 | H18: 136358900 | I18: 8.62 | J18: 8.782073 | K18: 1197513814 | L18: 628 | M18: 0 | N18: 6.982 | O18: 0 | P18: 23/04/2026 | Q18: 12/04/2028 | R18: 0 | S18: 2.9562998e+10 | T18: 2.9136856e+10 | U18: GOBMEX | V18: IDDIS | W18: 2.9176666e+10 | X18: MXBIGO000YY4 | Y18: HR+1
B19: DEUDAOP | C19: 23/07/2026 | D19: D | E19: BI | F19: CETES | G19: 280217 | H19: 89099875 | I19: 8.65 | J19: 8.907592 | K19: 7.9366533e+08 | L19: 573 | M19: 0 | N19: 6.863 | O19: 0 | P19: 26/02/2026 | Q19: 17/02/2028 | R19: 0 | S19: 2.9562998e+10 | T19: 2.9136856e+10 | U19: GOBMEX | V19: IDDIS | W19: 2.9176666e+10 | X19: MXBIGO000YP2 | Y19: HR+1
B20: DEUDAOP | C20: 23/07/2026 | D20: D | E20: BI | F20: CETES | G20: 270902 | H20: 197000000 | I20: 8.83 | J20: 9.247807 | K20: 1821817979 | L20: 405 | M20: 0 | N20: 6.686 | O20: 0 | P20: 11/09/2025 | Q20: 02/09/2027 | R20: 0 | S20: 2.9562998e+10 | T20: 2.9136856e+10 | U20: GOBMEX | V20: IDDIS | W20: 2.9176666e+10 | X20: MXBIGO000Y59 | Y20: HR+1
B21: DEUDAOP | C21: 23/07/2026 | D21: D | E21: BI | F21: CETES | G21: 260820 | H21: 14535000 | I21: 9.55 | J21: 9.951784 | K21: 1.4464918e+08 | L21: 27 | M21: 0 | N21: 6.429 | O21: 0 | P21: 21/08/2025 | Q21: 20/08/2026 | R21: 0 | S21: 2.9562998e+10 | T21: 2.9136856e+10 | U21: GOBMEX | V21: IDDIS | W21: 2.9176666e+10 | X21: MXBIGO000Y34 | Y21: HR+1
B22: DEUDAOP | C22: 23/07/2026 | D22: D | E22: BI | F22: CETES | G22: 260917 | H22: 85682400 | I22: 9.73 | J22: 9.901147 | K22: 8.4835404e+08 | L22: 55 | M22: 0 | N22: 6.47 | O22: 0 | P22: 18/09/2025 | Q22: 17/09/2026 | R22: 0 | S22: 2.9562998e+10 | T22: 2.9136856e+10 | U22: GOBMEX | V22: IDDIS | W22: 2.9176666e+10 | X22: MXBIGO000WN1 | Y22: HR+1
B23: DEUDAOP | C23: 23/07/2026 | D23: D | E23: BI | F23: CETES | G23: 261001 | H23: 26330000 | I23: 9.47 | J23: 9.875828 | K23: 2.6003055e+08 | L23: 69 | M23: 0 | N23: 6.479 | O23: 0 | P23: 10/10/2024 | Q23: 01/10/2026 | R23: 0 | S23: 2.9562998e+10 | T23: 2.9136856e+10 | U23: GOBMEX | V23: IDDIS | W23: 2.9176666e+10 | X23: MXBIGO000WO9 | Y23: HR+1
B24: DEUDAOP | C24: 23/07/2026 | D24: D | E24: BI | F24: CETES | G24: 270708 | H24: 273148662 | I24: 8.93 | J24: 9.361114 | K24: 2.5569758e+09 | L24: 349 | M24: 0 | N24: 6.59 | O24: 0 | P24: 17/07/2025 | Q24: 08/07/2027 | R24: 0 | S24: 2.9562998e+10 | T24: 2.9136856e+10 | U24: GOBMEX | V24: IDDIS | W24: 2.9176666e+10 | X24: MXBIGO000XW0 | Y24: HR+1
B25: DEUDAOP | C25: 23/07/2026 | D25: D | E25: BI | F25: CETES | G25: 261210 | H25: 40054109 | I25: 9.33 | J25: 9.748196 | K25: 3.9045531e+08 | L25: 139 | M25: 0 | N25: 6.522 | O25: 0 | P25: 11/12/2025 | Q25: 10/12/2026 | R25: 0 | S25: 2.9562998e+10 | T25: 2.9136856e+10 | U25: GOBMEX | V25: IDDIS | W25: 2.9176666e+10 | X25: MXBIGO000YI7 | Y25: HR+1
B26: DEUDAOP | C26: 23/07/2026 | D26: D | E26: BI | F26: CETES | G26: 270121 | H26: 86175200 | I26: 9.25 | J26: 9.670824 | K26: 8.3338519e+08 | L26: 181 | M26: 0 | N26: 6.547 | O26: 0 | P26: 30/01/2025 | Q26: 21/01/2027 | R26: 0 | S26: 2.9562998e+10 | T26: 2.9136856e+10 | U26: GOBMEX | V26: IDDIS | W26: 2.9176666e+10 | X26: MXBIGO000X68 | Y26: HR+1
B27: DEUDAOP | C27: 23/07/2026 | D27: D | E27: BI | F27: CETES | G27: 270318 | H27: 59050000 | I27: 9.14 | J27: 9.570309 | K27: 5.6512675e+08 | L27: 237 | M27: 0 | N27: 6.527 | O27: 0 | P27: 27/03/2025 | Q27: 18/03/2027 | R27: 0 | S27: 2.9562998e+10 | T27: 2.9136856e+10 | U27: GOBMEX | V27: IDDIS | W27: 2.9176666e+10 | X27: MXBIGO000XE8 | Y27: HR+1
B28: DEUDAOP | C28: 23/07/2026 | D28: D | E28: BI | F28: CETES | G28: 270429 | H28: 16199060 | I28: 9.32 | J28: 9.496237 | K28: 1.5383011e+08 | L28: 279 | M28: 0 | N28: 6.5 | O28: 0 | P28: 30/04/2026 | Q28: 29/04/2027 | R28: 0 | S28: 2.9562998e+10 | T28: 2.9136856e+10 | U28: GOBMEX | V28: IDDIS | W28: 2.9176666e+10 | X28: MXBIGO000Z09 | Y28: HR+1
B29: DEUDAOP | C29: 23/07/2026 | D29: D | E29: BI | F29: CETES | G29: 270513 | H29: 93000000 | I29: 9.03 | J29: 9.464631 | K29: 880210683 | L29: 293 | M29: 0 | N29: 6.578 | O29: 0 | P29: 22/05/2025 | Q29: 13/05/2027 | R29: 0 | S29: 2.9562998e+10 | T29: 2.9136856e+10 | U29: GOBMEX | V29: IDDIS | W29: 2.9176666e+10 | X29: MXBIGO000XO7 | Y29: HR+1
B30: DEUDAOP | C30: 23/07/2026 | D30: D | E30: BI | F30: CETES | G30: 261126 | H30: 45000000 | I30: 9.36 | J30: 9.772982 | K30: 439784190 | L30: 125 | M30: 0 | N30: 6.538 | O30: 0 | P30: 05/12/2024 | Q30: 26/11/2026 | R30: 0 | S30: 2.9562998e+10 | T30: 2.9136856e+10 | U30: GOBMEX | V30: IDDIS | W30: 2.9176666e+10 | X30: MXBIGO000WW2 | Y30: HR+1
B31: DEUDAOP | C31: 23/07/2026 | D31: D | E31: CHD | F31: BSANT | G31: 2945000 | H31: 44298 | I31: 17.99 | J31: 17.5269 | K31: 776415.91 | L31: 0 | M31: 0 | N31: 0 | O31: 0 | P31: 02/02/2021 | R31: 0 | S31: 2.9562998e+10 | T31: 2.9136856e+10 | U31: BANSAN | V31: IDDIS | W31: 2.9176666e+10 | Y31: N/A
B32: DEUDAOP | C32: 23/07/2026 | D32: D | E32: CHD | F32: JPMOR | G32: 3584000 | H32: 104921 | I32: 18.04 | J32: 17.565558 | K32: 1843009.9 | L32: 0 | M32: 0 | N32: 3.5 | O32: 0 | P32: 02/02/2021 | R32: 0 | S32: 2.9562998e+10 | T32: 2.9136856e+10 | U32: JPM | V32: IDDIS | W32: 2.9176666e+10 | Y32: N/A
B33: DEUDAOP | C33: 23/07/2026 | D33: D | E33: D8 | F33: CAFN28 | G33: 1-20 | H33: 24064 | I33: 1032.66 | J33: 1043.8084 | K33: 25118206 | L33: 593 | M33: 0 | N33: 8.5 | O33: 0 | P33: 08/03/2018 | Q33: 08/03/2028 | R33: 46 | S33: 2.9562998e+10 | T33: 2.9136856e+10 | U33: CAF | V33: IDDIS | W33: 2.9176666e+10 | X33: XS1789715064 | Y33: AA
B34: DEUDAOP | C34: 23/07/2026 | D34: D | E34: IM | F34: BPAG28 | G34: 261105 | H34: 500000 | I34: 100.06 | J34: 100.1242 | K34: 50062100 | L34: 104 | M34: 0 | N34: 6.5 | O34: 0 | P34: 09/11/2023 | Q34: 05/11/2026 | R34: 20 | S34: 2.9562998e+10 | T34: 2.9136856e+10 | U34: IPAB | V34: IDDIS | W34: 2.9176666e+10 | X34: MXIMBP0601R3 | Y34: HR AAA
B35: DEUDAOP | C35: 23/07/2026 | D35: D | E35: IM | F35: BPAG28 | G35: 260806 | H35: 2000000 | I35: 100.21 | J35: 100.26789 | K35: 200535772 | L35: 13 | M35: 0 | N35: 6.5 | O35: 0 | P35: 10/08/2023 | Q35: 06/08/2026 | R35: 13 | S35: 2.9562998e+10 | T35: 2.9136856e+10 | U35: IPAB | V35: IDDIS | W35: 2.9176666e+10 | X35: MXIMBP0601Q5 | Y35: HR AAA
B36: DEUDAOP | C36: 23/07/2026 | D36: D | E36: IQ | F36: BPAG91 | G36: 280511 | H36: 1000000 | I36: 100.95 | J36: 101.01847 | K36: 101018471 | L36: 657 | M36: 0 | N36: 6.51 | O36: 0 | P36: 18/05/2023 | Q36: 11/05/2028 | R36: 20 | S36: 2.9562998e+10 | T36: 2.9136856e+10 | U36: IPAB | V36: IDDIS | W36: 2.9176666e+10 | X36: MXIQBP0701P6 | Y36: HR AAA
B37: DEUDAOP | C37: 23/07/2026 | D37: D | E37: IQ | F37: BPAG91 | G37: 280907 | H37: 512000 | I37: 100.39 | J37: 100.44859 | K37: 51429679 | L37: 776 | M37: 0 | N37: 6.48 | O37: 0 | P37: 14/09/2023 | Q37: 07/09/2028 | R37: 48 | S37: 2.9562998e+10 | T37: 2.9136856e+10 | U37: IPAB | V37: IDDIS | W37: 2.9176666e+10 | X37: MXIQBP0701Q4 | Y37: HR AAA
B38: DEUDAOP | C38: 23/07/2026 | D38: D | E38: IQ | F38: BPAG91 | G38: 270909 | H38: 500000 | I38: 100.6 | J38: 100.65327 | K38: 50326638 | L38: 412 | M38: 0 | N38: 6.48 | O38: 0 | P38: 15/09/2022 | Q38: 09/09/2027 | R38: 48 | S38: 2.9562998e+10 | T38: 2.9136856e+10 | U38: IPAB | V38: IDDIS | W38: 2.9176666e+10 | X38: MXIQBP0701N1 | Y38: HR AAA
B39: DEUDAOP | C39: 23/07/2026 | D39: D | E39: IQ | F39: BPAG91 | G39: 270506 | H39: 900000 | I39: 101.35 | J39: 101.39661 | K39: 91256948 | L39: 286 | M39: 0 | N39: 6.74 | O39: 0 | P39: 12/05/2022 | Q39: 06/05/2027 | R39: 13 | S39: 2.9562998e+10 | T39: 2.9136856e+10 | U39: IPAB | V39: IDDIS | W39: 2.9176666e+10 | X39: MXIQBP0701M3 | Y39: HR AAA
B40: DEUDAOP | C40: 23/07/2026 | D40: D | E40: IQ | F40: BPAG91 | G40: 260903 | H40: 400000 | I40: 100.87 | J40: 100.90378 | K40: 40361511 | L40: 41 | M40: 0 | N40: 6.56 | O40: 0 | P40: 09/09/2021 | Q40: 03/09/2026 | R40: 41 | S40: 2.9562998e+10 | T40: 2.9136856e+10 | U40: IPAB | V40: IDDIS | W40: 2.9176666e+10 | X40: MXIQBP0701K7 | Y40: HR AAA
...

Sheet Dividendos
A1: Posición | B1: SI | D1: =TODAY() -> 46230 | E1: BIVA | F1: COVAF
A2: Fecha Registro | B2: (Todas) | D2: Dividendos | E2: =COUNTA(B6:B99) -> 4 | F2: =COUNTIF(Histórico!B:B,D1) -> 1 | O2: Ruta Archivos:
A3: Ex date/Efectos | B3: (Todas) | F3: =IF(E2=F2,"OK","REVISAR") -> REVISAR | O3: C:\Home Office\Conciliaciones\
A5: Fondo | B5: Portfolio | C5: Tipo de derecho | D5: Posición. | E5: Estatus | F5: ISIN | G5: Fecha Pago | H5: Proporción/importe
A6: FF_FVIA_16 | B6: SVIVE20 | C6: Distribución en efectivo | D6: 46983 | E6: Aplicado | F6: MXFFFV000007 | G6: 27/07/2026 | H6: SERIE(S) '16' CUPON VIGENTE 0 CUPON PAGO 0 A MXN $ 0.3889785940707460
A7: FF_FVIA_16 | B7: SVIVE35 | C7: Distribución en efectivo | D7: 80514 | E7: Aplicado | F7: MXFFFV000007 | G7: 27/07/2026 | H7: SERIE(S) '16' CUPON VIGENTE 0 CUPON PAGO 0 A MXN $ 0.3889785940707460
A8: FF_FVIA_16 | B8: SVIVE50 | C8: Distribución en efectivo | D8: 18838 | E8: Aplicado | F8: MXFFFV000007 | G8: 27/07/2026 | H8: SERIE(S) '16' CUPON VIGENTE 0 CUPON PAGO 0 A MXN $ 0.3889785940707460
A9: 1A_PG_* | B9: SAM-RED | C9: Dividendo en efectivo | D9: 440 | E9: Aplicado | F9: US7427181091 | G9: 17/08/2026 | H9: Option Number: "001" Option Type: "Cash" Default Option: "Yes" Gross Dividend Rate: "1.0885 USD" Option Number: "002" Option Type: "Security" Default Option: "No"

Sheet Histórico
B1: Ex Date | C1: FONDO | D1: EMISORA | E1: SERIE | F1: TV | G1: TIPO DERECHO | I1: FechaPago | J1: MONTO | K1: TITULOS | L1: PROVISION | M1: IMPTO. INTER. | N1: ISR | O1: FechaPago | P1: CUFIN | R1: FONDO | S1: EMISORA | T1: SERIE | U1: TV | V1: MONTO | W1: TITULOS | X1: PROVISION | Y1: IMPTO. INTER. | Z1: ISR | AB1: Monto Bruto | AC1: IMPTO. INTER. | AD1: ISR
B2: 45294 | C2: SAM-SP | D2: CSCO | E2: * | F2: 1A | G2: En efectivo (Moneda Extranjera) | J2: 0.39 | K2: 9460 | L2: 3689.4 | M2: 0.1 | N2: 0.1 | O2: 24/01/2024 | R2: =IF(C2="","",C2) -> SAM-SP | S2: =IF(D2="","",D2) -> CSCO | T2: =IF(E2="","",E2) -> * | U2: =IF(F2="","",F2) -> 1A | V2: 0.39 | W2: 9460 | X2: =V2*W2 -> 3689.4 | Y2: 0.1 | Z2: 0.1 | AB2: =L2-X2 -> 0 | AC2: =M2-Y2 -> 0 | AD2: =N2-Z2 -> 0
B3: 45295 | C3: SAM-RVG | D3: JPM | E3: * | F3: 1A | G3: En efectivo (Moneda Extranjera) | J3: 1.05 | K3: 10760 | L3: 11298 | M3: 0.1 | N3: 0.1 | O3: 31/01/2024 | R3: =IF(C3="","",C3) -> SAM-RVG | S3: =IF(D3="","",D3) -> JPM | T3: =IF(E3="","",E3) -> * | U3: =IF(F3="","",F3) -> 1A | V3: 1.05 | W3: 10760 | X3: =V3*W3 -> 11298 | Y3: 0.1 | Z3: 0.1 | AB3: =L3-X3 -> 0 | AC3: =M3-Y3 -> 0 | AD3: =N3-Z3 -> 0
B4: 45295 | C4: SAM-SP | D4: AXP | E4: * | F4: 1A | G4: En efectivo (Moneda Extranjera) | J4: 0.6 | K4: 5300 | L4: 3180 | M4: 0.1 | N4: 0.1 | O4: 09/02/2024 | R4: =IF(C4="","",C4) -> SAM-SP | S4: =IF(D4="","",D4) -> AXP | T4: =IF(E4="","",E4) -> * | U4: =IF(F4="","",F4) -> 1A | V4: 0.6 | W4: 5300 | X4: =V4*W4 -> 3180 | Y4: 0.1 | Z4: 0.1 | AB4: =L4-X4 -> 0 | AC4: =M4-Y4 -> 0 | AD4: =N4-Z4 -> 0
B5: 45295 | C5: SAM-SP | D5: JPM | E5: * | F5: 1A | G5: En efectivo (Moneda Extranjera) | J5: 1.05 | K5: 6960 | L5: 7308 | M5: 0.1 | N5: 0.1 | O5: 31/01/2024 | R5: =IF(C5="","",C5) -> SAM-SP | S5: =IF(D5="","",D5) -> JPM | T5: =IF(E5="","",E5) -> * | U5: =IF(F5="","",F5) -> 1A | V5: 1.05 | W5: 6960 | X5: =V5*W5 -> 7308 | Y5: 0.1 | Z5: 0.1 | AB5: =L5-X5 -> 0 | AC5: =M5-Y5 -> 0 | AD5: =N5-Z5 -> 0
B6: 45300 | C6: SAMEME2 | D6: INTU | E6: * | F6: 1A | G6: En efectivo (Moneda Extranjera) | J6: 0.9 | K6: 3800 | L6: 3420 | M6: 0.1 | N6: 0.1 | O6: 45309 | R6: =IF(C6="","",C6) -> SAMEME2 | S6: =IF(D6="","",D6) -> INTU | T6: =IF(E6="","",E6) -> * | U6: =IF(F6="","",F6) -> 1A | V6: 0.9 | W6: 3800 | X6: =V6*W6 -> 3420 | Y6: 0.1 | Z6: 0.1 | AB6: =L6-X6 -> 0 | AC6: =M6-Y6 -> 0 | AD6: =N6-Z6 -> 0
B7: 45300 | C7: EURO-EQ | D7: IBE | E7: N | F7: 1A | G7: En efectivo (Moneda Extranjera) | J7: 0.202 | K7: 16718 | L7: 3377.04 | M7: 0.1 | N7: 0.1 | O7: 45322 | R7: =IF(C7="","",C7) -> EURO-EQ | S7: =IF(D7="","",D7) -> IBE | T7: =IF(E7="","",E7) -> N | U7: =IF(F7="","",F7) -> 1A | V7: 0.202 | W7: 16718 | X7: =V7*W7 -> 3377.036 | Y7: 0.1 | Z7: 0.1 | AB7: =L7-X7 -> 0.004 | AC7: =M7-Y7 -> 0 | AD7: =N7-Z7 -> 0
B8: 45301 | C8: SAM-AF | D8: GRUMA | E8: B | F8: 1 | G8: En efectivo (Moneda Nacional) | J8: 1.35 | K8: 65200 | L8: 88020 | M8: 0 | N8: 0.1 | O8: 12/01/2024 | R8: =IF(C8="","",C8) -> SAM-AF | S8: =IF(D8="","",D8) -> GRUMA | T8: =IF(E8="","",E8) -> B | U8: =IF(F8="","",F8) -> 1 | V8: 1.35 | W8: 65200 | X8: =V8*W8 -> 88020 | Y8: 0 | Z8: 0.1 | AB8: =L8-X8 -> 0 | AC8: =M8-Y8 -> 0 | AD8: =N8-Z8 -> 0
B9: 45301 | C9: SAM-ESG | D9: GRUMA | E9: B | F9: 1 | G9: En efectivo (Moneda Nacional) | J9: 1.35 | K9: 128000 | L9: 172800 | M9: 0 | N9: 0.1 | O9: 12/01/2024 | R9: =IF(C9="","",C9) -> SAM-ESG | S9: =IF(D9="","",D9) -> GRUMA | T9: =IF(E9="","",E9) -> B | U9: =IF(F9="","",F9) -> 1 | V9: 1.35 | W9: 128000 | X9: =V9*W9 -> 172800 | Y9: 0 | Z9: 0.1 | AB9: =L9-X9 -> 0 | AC9: =M9-Y9 -> 0 | AD9: =N9-Z9 -> 0
B10: 45301 | C10: ST&ER-C | D10: GRUMA | E10: B | F10: 1 | G10: En efectivo (Moneda Nacional) | J10: 1.35 | K10: 26100 | L10: 35235 | M10: 0 | N10: 0.1 | O10: 12/01/2024 | R10: =IF(C10="","",C10) -> ST&ER-C | S10: =IF(D10="","",D10) -> GRUMA | T10: =IF(E10="","",E10) -> B | U10: =IF(F10="","",F10) -> 1 | V10: 1.35 | W10: 26100 | X10: =V10*W10 -> 35235 | Y10: 0 | Z10: 0.1 | AB10: =L10-X10 -> 0 | AC10: =M10-Y10 -> 0 | AD10: =N10-Z10 -> 0
B11: 45301 | C11: STER-OP | D11: GRUMA | E11: B | F11: 1 | G11: En efectivo (Moneda Nacional) | J11: 1.35 | K11: 769000 | L11: 1038150 | M11: 0 | N11: 0.1 | O11: 12/01/2024 | R11: =IF(C11="","",C11) -> STER-OP | S11: =IF(D11="","",D11) -> GRUMA | T11: =IF(E11="","",E11) -> B | U11: =IF(F11="","",F11) -> 1 | V11: 1.35 | W11: 769000 | X11: =V11*W11 -> 1038150 | Y11: 0 | Z11: 0.1 | AB11: =L11-X11 -> 0 | AC11: =M11-Y11 -> 0 | AD11: =N11-Z11 -> 0
B12: 45301 | C12: USA-EQ | D12: ORCL | E12: * | F12: 1A | G12: En efectivo (Moneda Extranjera) | J12: 0.4 | K12: 109490 | L12: 43796 | M12: 0.1 | N12: 0.1 | O12: 25/01/2024 | R12: =IF(C12="","",C12) -> USA-EQ | S12: =IF(D12="","",D12) -> ORCL | T12: =IF(E12="","",E12) -> * | U12: =IF(F12="","",F12) -> 1A | V12: 0.4 | W12: 109490 | X12: =V12*W12 -> 43796 | Y12: 0.1 | Z12: 0.1 | AB12: =L12-X12 -> 0 | AC12: =M12-Y12 -> 0 | AD12: =N12-Z12 -> 0
B13: 45302 | C13: SAMEMEC | D13: AHT | E13: N | F13: 1A | G13: En efectivo (Moneda Extranjera) | J13: 0.1575 | K13: 52350 | L13: 8245.13 | M13: 0.1 | N13: 0.1 | O13: 08/02/2024 | R13: =IF(C13="","",C13) -> SAMEMEC | S13: =IF(D13="","",D13) -> AHT | T13: =IF(E13="","",E13) -> N | U13: =IF(F13="","",F13) -> 1A | V13: 0.1575 | W13: 52350 | X13: =V13*W13 -> 8245.125 | Y13: 0.1 | Z13: 0.1 | AB13: =L13-X13 -> 0.005 | AC13: =M13-Y13 -> 0 | AD13: =N13-Z13 -> 0
B14: 45302 | C14: SAMEME1 | D14: AHT | E14: N | F14: 1A | G14: En efectivo (Moneda Extranjera) | J14: 0.1575 | K14: 60309 | L14: 9498.67 | M14: 0.1 | N14: 0.1 | O14: 08/02/2024 | R14: =IF(C14="","",C14) -> SAMEME1 | S14: =IF(D14="","",D14) -> AHT | T14: =IF(E14="","",E14) -> N | U14: =IF(F14="","",F14) -> 1A | V14: 0.1575 | W14: 60309 | X14: =V14*W14 -> 9498.6675 | Y14: 0.1 | Z14: 0.1 | AB14: =L14-X14 -> 0.0025 | AC14: =M14-Y14 -> 0 | AD14: =N14-Z14 -> 0
B15: 45302 | C15: SAMEME2 | D15: AHT | E15: N | F15: 1A | G15: En efectivo (Moneda Extranjera) | J15: 0.1575 | K15: 31864 | L15: 5018.58 | M15: 0.1 | N15: 0.1 | O15: 08/02/2024 | R15: =IF(C15="","",C15) -> SAMEME2 | S15: =IF(D15="","",D15) -> AHT | T15: =IF(E15="","",E15) -> N | U15: =IF(F15="","",F15) -> 1A | V15: 0.1575 | W15: 31864 | X15: =V15*W15 -> 5018.58 | Y15: 0.1 | Z15: 0.1 | AB15: =L15-X15 -> 0 | AC15: =M15-Y15 -> 0 | AD15: =N15-Z15 -> 0
B16: 45302 | C16: SAM-AF | D16: VESTA | E16: * | F16: 1 | G16: En efectivo (Moneda Extranjera) | J16: 0.017157 | K16: 165000 | L16: 2830.87 | M16: 0 | N16: 0.1 | O16: 15/01/2024 | R16: =IF(C16="","",C16) -> SAM-AF | S16: =IF(D16="","",D16) -> VESTA | T16: =IF(E16="","",E16) -> * | U16: =IF(F16="","",F16) -> 1 | V16: 0.017157 | W16: 165000 | X16: =V16*W16 -> 2830.905 | Y16: 0 | Z16: 0.1 | AB16: =L16-X16 -> -0.035 | AC16: =M16-Y16 -> 0 | AD16: =N16-Z16 -> 0
B17: 45302 | C17: SAM-ESG | D17: VESTA | E17: * | F17: 1 | G17: En efectivo (Moneda Extranjera) | J17: 0.017157 | K17: 458000 | L17: 7857.8 | M17: 0 | N17: 0.1 | O17: 15/01/2024 | R17: =IF(C17="","",C17) -> SAM-ESG | S17: =IF(D17="","",D17) -> VESTA | T17: =IF(E17="","",E17) -> * | U17: =IF(F17="","",F17) -> 1 | V17: 0.017157 | W17: 458000 | X17: =V17*W17 -> 7857.906 | Y17: 0 | Z17: 0.1 | AB17: =L17-X17 -> -0.106 | AC17: =M17-Y17 -> 0 | AD17: =N17-Z17 -> 0
B18: 45302 | C18: ST&ER-C | D18: VESTA | E18: * | F18: 1 | G18: En efectivo (Moneda Extranjera) | J18: 0.017157 | K18: 118763 | L18: 2037.59 | M18: 0 | N18: 0.1 | O18: 15/01/2024 | R18: =IF(C18="","",C18) -> ST&ER-C | S18: =IF(D18="","",D18) -> VESTA | T18: =IF(E18="","",E18) -> * | U18: =IF(F18="","",F18) -> 1 | V18: 0.017157 | W18: 118763 | X18: =V18*W18 -> 2037.6168 | Y18: 0 | Z18: 0.1 | AB18: =L18-X18 -> -0.026791 | AC18: =M18-Y18 -> 0 | AD18: =N18-Z18 -> 0
B19: 45302 | C19: STER-OP | D19: VESTA | E19: * | F19: 1 | G19: En efectivo (Moneda Extranjera) | J19: 0.017157 | K19: 3625000 | L19: 62193.27 | M19: 0 | N19: 0.1 | O19: 15/01/2024 | R19: =IF(C19="","",C19) -> STER-OP | S19: =IF(D19="","",D19) -> VESTA | T19: =IF(E19="","",E19) -> * | U19: =IF(F19="","",F19) -> 1 | V19: 0.017157 | W19: 3625000 | X19: =V19*W19 -> 62194.125 | Y19: 0 | Z19: 0.1 | AB19: =L19-X19 -> -0.855 | AC19: =M19-Y19 -> 0 | AD19: =N19-Z19 -> 0
B20: 45303 | C20: SAM-RVG | D20: ABBV | E20: * | F20: 1A | G20: En efectivo (Moneda Extranjera) | J20: 1.55 | K20: 4110 | L20: 6370.5 | M20: 0.1 | N20: 0.1 | O20: 45337 | R20: =IF(C20="","",C20) -> SAM-RVG | S20: =IF(D20="","",D20) -> ABBV | T20: =IF(E20="","",E20) -> * | U20: =IF(F20="","",F20) -> 1A | V20: 1.55 | W20: 4110 | X20: =V20*W20 -> 6370.5 | Y20: 0.1 | Z20: 0.1 | AB20: =L20-X20 -> 0 | AC20: =M20-Y20 -> 0 | AD20: =N20-Z20 -> 0
B21: 45308 | C21: SAM-RVG | D21: ACN | E21: N | F21: 1A | G21: En efectivo (Moneda Extranjera) | J21: 1.29 | K21: 2030 | L21: 2618.7 | M21: 0.25 | N21: 0.1 | O21: 45337 | R21: =IF(C21="","",C21) -> SAM-RVG | S21: =IF(D21="","",D21) -> ACN | T21: =IF(E21="","",E21) -> N | U21: =IF(F21="","",F21) -> 1A | V21: 1.29 | W21: 2030 | X21: =V21*W21 -> 2618.7 | Y21: 0.25 | Z21: 0.1 | AB21: =L21-X21 -> 0 | AC21: =M21-Y21 -> 0 | AD21: =N21-Z21 -> 0
B22: 45308 | C22: SAM-SP | D22: ACN | E22: N | F22: 1A | G22: En efectivo (Moneda Extranjera) | J22: 1.29 | K22: 1390 | L22: 1793.1 | M22: 0.25 | N22: 0.1 | O22: 45337 | R22: =IF(C22="","",C22) -> SAM-SP | S22: =IF(D22="","",D22) -> ACN | T22: =IF(E22="","",E22) -> N | U22: =IF(F22="","",F22) -> 1A | V22: 1.29 | W22: 1390 | X22: =V22*W22 -> 1793.1 | Y22: 0.25 | Z22: 0.1 | AB22: =L22-X22 -> 0 | AC22: =M22-Y22 -> 0 | AD22: =N22-Z22 -> 0
B23: 45309 | C23: SAMEMEC | D23: RVTY | E23: * | F23: 1A | G23: En efectivo (Moneda Extranjera) | J23: 0.07 | K23: 19530 | L23: 1367.1 | M23: 0.1 | N23: 0.1 | O23: 09/02/2024 | R23: =IF(C23="","",C23) -> SAMEMEC | S23: =IF(D23="","",D23) -> RVTY | T23: =IF(E23="","",E23) -> * | U23: =IF(F23="","",F23) -> 1A | V23: 0.07 | W23: 19530 | X23: =V23*W23 -> 1367.1 | Y23: 0.1 | Z23: 0.1 | AB23: =L23-X23 -> 0 | AC23: =M23-Y23 -> 0 | AD23: =N23-Z23 -> 0
B24: 45309 | C24: SAMEME1 | D24: RVTY | E24: * | F24: 1A | G24: En efectivo (Moneda Extranjera) | J24: 0.07 | K24: 13671 | L24: 956.97 | M24: 0.1 | N24: 0.1 | O24: 09/02/2024 | R24: =IF(C24="","",C24) -> SAMEME1 | S24: =IF(D24="","",D24) -> RVTY | T24: =IF(E24="","",E24) -> * | U24: =IF(F24="","",F24) -> 1A | V24: 0.07 | W24: 13671 | X24: =V24*W24 -> 956.97 | Y24: 0.1 | Z24: 0.1 | AB24: =L24-X24 -> 0 | AC24: =M24-Y24 -> 0 | AD24: =N24-Z24 -> 0
B25: 45309 | C25: SAM-SP | D25: PG | E25: * | F25: 1A | G25: En efectivo (Moneda Extranjera) | J25: 0.9407 | K25: 8950 | L25: 8419.27 | M25: 0.1 | N25: 0.1 | O25: 15/02/2024 | R25: =IF(C25="","",C25) -> SAM-SP | S25: =IF(D25="","",D25) -> PG | T25: =IF(E25="","",E25) -> * | U25: =IF(F25="","",F25) -> 1A | V25: 0.9407 | W25: 8950 | X25: =V25*W25 -> 8419.265 | Y25: 0.1 | Z25: 0.1 | AB25: =L25-X25 -> 0.005 | AC25: =M25-Y25 -> 0 | AD25: =N25-Z25 -> 0
B26: 45310 | C26: SAMEMEC | D26: CVS | E26: * | F26: 1A | G26: En efectivo (Moneda Extranjera) | J26: 0.665 | K26: 22040 | L26: 14656.6 | M26: 0.1 | N26: 0.1 | O26: 45323 | R26: =IF(C26="","",C26) -> SAMEMEC | S26: =IF(D26="","",D26) -> CVS | T26: =IF(E26="","",E26) -> * | U26: =IF(F26="","",F26) -> 1A | V26: 0.665 | W26: 22040 | X26: =V26*W26 -> 14656.6 | Y26: 0.1 | Z26: 0.1 | AB26: =L26-X26 -> 0 | AC26: =M26-Y26 -> 0 | AD26: =N26-Z26 -> 0
B27: 45310 | C27: SAMEME1 | D27: CVS | E27: * | F27: 1A | G27: En efectivo (Moneda Extranjera) | J27: 0.665 | K27: 30469 | L27: 20261.89 | M27: 0.1 | N27: 0.1 | O27: 45323 | R27: =IF(C27="","",C27) -> SAMEME1 | S27: =IF(D27="","",D27) -> CVS | T27: =IF(E27="","",E27) -> * | U27: =IF(F27="","",F27) -> 1A | V27: 0.665 | W27: 30469 | X27: =V27*W27 -> 20261.885 | Y27: 0.1 | Z27: 0.1 | AB27: =L27-X27 -> 0.005 | AC27: =M27-Y27 -> 0 | AD27: =N27-Z27 -> 0
B28: 45310 | C28: SAM-RED | D28: CL | E28: * | F28: 1A | G28: En efectivo (Moneda Extranjera) | J28: 0.48 | K28: 1770 | L28: 849.6 | M28: 0.1 | N28: 0.1 | O28: 45337 | R28: =IF(C28="","",C28) -> SAM-RED | S28: =IF(D28="","",D28) -> CL | T28: =IF(E28="","",E28) -> * | U28: =IF(F28="","",F28) -> 1A | V28: 0.48 | W28: 1770 | X28: =V28*W28 -> 849.6 | Y28: 0.1 | Z28: 0.1 | AB28: =L28-X28 -> 0 | AC28: =M28-Y28 -> 0 | AD28: =N28-Z28 -> 0
B29: 45310 | C29: SAM-SP | D29: CAT | E29: * | F29: 1A | G29: En efectivo (Moneda Extranjera) | J29: 1.3 | K29: 4120 | L29: 5356 | M29: 0.1 | N29: 0.1 | O29: 45342 | R29: =IF(C29="","",C29) -> SAM-SP | S29: =IF(D29="","",D29) -> CAT | T29: =IF(E29="","",E29) -> * | U29: =IF(F29="","",F29) -> 1A | V29: 1.3 | W29: 4120 | X29: =V29*W29 -> 5356 | Y29: 0.1 | Z29: 0.1 | AB29: =L29-X29 -> 0 | AC29: =M29-Y29 -> 0 | AD29: =N29-Z29 -> 0
B30: 45315 | C30: SAM-RVG | D30: MMC | E30: * | F30: 1A | G30: En efectivo (Moneda Extranjera) | J30: 0.71 | K30: 7410 | L30: 5261.1 | M30: 0.1 | N30: 0.1 | O30: 45337 | R30: =IF(C30="","",C30) -> SAM-RVG | S30: =IF(D30="","",D30) -> MMC | T30: =IF(E30="","",E30) -> * | U30: =IF(F30="","",F30) -> 1A | V30: 0.71 | W30: 7410 | X30: =V30*W30 -> 5261.1 | Y30: 0.1 | Z30: 0.1 | AB30: =L30-X30 -> 0 | AC30: =M30-Y30 -> 0 | AD30: =N30-Z30 -> 0
B31: 45316 | C31: SAM-SP | D31: PFE | E31: * | F31: 1A | G31: En efectivo (Moneda Extranjera) | J31: 0.42 | K31: 23690 | L31: 9949.8 | M31: 0.1 | N31: 0.1 | O31: 45352 | R31: =IF(C31="","",C31) -> SAM-SP | S31: =IF(D31="","",D31) -> PFE | T31: =IF(E31="","",E31) -> * | U31: =IF(F31="","",F31) -> 1A | V31: 0.42 | W31: 23690 | X31: =V31*W31 -> 9949.8 | Y31: 0.1 | Z31: 0.1 | AB31: =L31-X31 -> 0 | AC31: =M31-Y31 -> 0 | AD31: =N31-Z31 -> 0
B32: 45316 | C32: SAMUSCP | D32: USFR | E32: * | F32: 1I | G32: En efectivo (Moneda Extranjera) | J32: 0.227 | K32: 74352 | L32: 16877.9 | M32: 0.1 | N32: 0.1 | O32: 45321 | R32: =IF(C32="","",C32) -> SAMUSCP | S32: =IF(D32="","",D32) -> USFR | T32: =IF(E32="","",E32) -> * | U32: =IF(F32="","",F32) -> 1I | V32: 0.227 | W32: 74352 | X32: =V32*W32 -> 16877.904 | Y32: 0.1 | Z32: 0.1 | AB32: =L32-X32 -> -0.004 | AC32: =M32-Y32 -> 0 | AD32: =N32-Z32 -> 0
B33: 45317 | C33: SAM-AF | D33: FIBRAMQ | E33: 12 | F33: CF | G33: Distribución del Resultado Fiscal de FIBRAS | J33: 0.525 | K33: 157000 | L33: 82425 | M33: 0 | N33: 0.3 | O33: 45321 | R33: =IF(C33="","",C33) -> SAM-AF | S33: =IF(D33="","",D33) -> FIBRAMQ | T33: =IF(E33="","",E33) -> 12 | U33: =IF(F33="","",F33) -> CF | V33: 0.525 | W33: 157000 | X33: =V33*W33 -> 82425 | Y33: 0 | Z33: 0.3 | AB33: =L33-X33 -> 0 | AC33: =M33-Y33 -> 0 | AD33: =N33-Z33 -> 0
B34: 45317 | C34: SAM-ESG | D34: FIBRAMQ | E34: 12 | F34: CF | G34: Distribución del Resultado Fiscal de FIBRAS | J34: 0.525 | K34: 271000 | L34: 142275 | M34: 0 | N34: 0.3 | O34: 45321 | R34: =IF(C34="","",C34) -> SAM-ESG | S34: =IF(D34="","",D34) -> FIBRAMQ | T34: =IF(E34="","",E34) -> 12 | U34: =IF(F34="","",F34) -> CF | V34: 0.525 | W34: 271000 | X34: =V34*W34 -> 142275 | Y34: 0 | Z34: 0.3 | AB34: =L34-X34 -> 0 | AC34: =M34-Y34 -> 0 | AD34: =N34-Z34 -> 0
B35: 45320 | C35: ELIGE-C | D35: NAFTRAC | E35: ISHRS | F35: 1B | G35: En efectivo (Moneda Nacional) | J35: 0.003297 | K35: 315420 | L35: 1039.98 | M35: 0 | N35: 0 | O35: 45322 | R35: =IF(C35="","",C35) -> ELIGE-C | S35: =IF(D35="","",D35) -> NAFTRAC | T35: =IF(E35="","",E35) -> ISHRS | U35: =IF(F35="","",F35) -> 1B | V35: 0.003297 | W35: 315420 | X35: =V35*W35 -> 1039.9397 | Y35: 0 | Z35: 0 | AB35: =L35-X35 -> 0.04026 | AC35: =M35-Y35 -> 0 | AD35: =N35-Z35 -> 0
B36: 45320 | C36: ELIGE-C | D36: NAFTRAC | E36: ISHRS | F36: 1B | G36: En efectivo (Moneda Nacional) | J36: 0.009109 | K36: 315420 | L36: 2873.3 | M36: 0 | N36: 0.1 | O36: 45322 | R36: =IF(C36="","",C36) -> ELIGE-C | S36: =IF(D36="","",D36) -> NAFTRAC | T36: =IF(E36="","",E36) -> ISHRS | U36: =IF(F36="","",F36) -> 1B | V36: 0.009109 | W36: 315420 | X36: =V36*W36 -> 2873.1608 | Y36: 0 | Z36: 0.1 | AB36: =L36-X36 -> 0.13922 | AC36: =M36-Y36 -> 0 | AD36: =N36-Z36 -> 0
B37: 45320 | C37: ELIGE-C | D37: NAFTRAC | E37: ISHRS | F37: 1B | G37: En efectivo (Moneda Nacional) | J37: 0.00753 | K37: 315420 | L37: 2375.24 | M37: 0 | N37: 0.1 | O37: 45322 | R37: =IF(C37="","",C37) -> ELIGE-C | S37: =IF(D37="","",D37) -> NAFTRAC | T37: =IF(E37="","",E37) -> ISHRS | U37: =IF(F37="","",F37) -> 1B | V37: 0.00753 | W37: 315420 | X37: =V37*W37 -> 2375.1126 | Y37: 0 | Z37: 0.1 | AB37: =L37-X37 -> 0.1274 | AC37: =M37-Y37 -> 0 | AD37: =N37-Z37 -> 0
B38: 45320 | C38: ELIGE-P | D38: NAFTRAC | E38: ISHRS | F38: 1B | G38: En efectivo (Moneda Nacional) | J38: 0.00753 | K38: 5450875 | L38: 41047.33 | M38: 0 | N38: 0.1 | O38: 45322 | R38: =IF(C38="","",C38) -> ELIGE-P | S38: =IF(D38="","",D38) -> NAFTRAC | T38: =IF(E38="","",E38) -> ISHRS | U38: =IF(F38="","",F38) -> 1B | V38: 0.00753 | W38: 5450875 | X38: =V38*W38 -> 41045.089 | Y38: 0 | Z38: 0.1 | AB38: =L38-X38 -> 2.24125 | AC38: =M38-Y38 -> 0 | AD38: =N38-Z38 -> 0
B39: 45320 | C39: ELIGE-P | D39: NAFTRAC | E39: ISHRS | F39: 1B | G39: En efectivo (Moneda Nacional) | J39: 0.003297 | K39: 5450875 | L39: 17972.31 | M39: 0 | N39: 0 | O39: 45322 | R39: =IF(C39="","",C39) -> ELIGE-P | S39: =IF(D39="","",D39) -> NAFTRAC | T39: =IF(E39="","",E39) -> ISHRS | U39: =IF(F39="","",F39) -> 1B | V39: 0.003297 | W39: 5450875 | X39: =V39*W39 -> 17971.535 | Y39: 0 | Z39: 0 | AB39: =L39-X39 -> 0.775125 | AC39: =M39-Y39 -> 0 | AD39: =N39-Z39 -> 0
B40: 45320 | C40: ELIGE-P | D40: NAFTRAC | E40: ISHRS | F40: 1B | G40: En efectivo (Moneda Nacional) | J40: 0.009109 | K40: 5450875 | L40: 49654.36 | M40: 0 | N40: 0.1 | O40: 45322 | R40: =IF(C40="","",C40) -> ELIGE-P | S40: =IF(D40="","",D40) -> NAFTRAC | T40: =IF(E40="","",E40) -> ISHRS | U40: =IF(F40="","",F40) -> 1B | V40: 0.009109 | W40: 5450875 | X40: =V40*W40 -> 49652.02 | Y40: 0 | Z40: 0.1 | AB40: =L40-X40 -> 2.339625 | AC40: =M40-Y40 -> 0 | AD40: =N40-Z40 -> 0
...

Sheet Div2
A1: Posición | B1: SI
A2: Fecha Registro | B2: (Todas) | O2: Ruta Archivos:
A3: Ex date/Efectos | B3: (Todas) | O3: C:\Home Office\Conciliaciones\
A5: Fondo | B5: Tipo de derecho | C5: Estatus | D5: ISIN | E5: Fecha Pago | F5: Proporción/importe
A6: 1A_PG_* | B6: Dividendo en efectivo | C6: Aplicado | D6: US7427181091 | E6: 17/08/2026 | F6: Option Number: "001" Option Type: "Cash" Default Option: "Yes" Gross Dividend Rate: "1.0885 USD" Option Number: "002" Option Type: "Security" Default Option: "No"
A7: FF_FVIA_16 | B7: Distribución en efectivo | C7: Aplicado | D7: MXFFFV000007 | E7: 27/07/2026 | F7: SERIE(S) '16' CUPON VIGENTE 0 CUPON PAGO 0 A MXN $ 0.3889785940707460
G23: 0.2121 - Tasa actual - Tasa de impuestos Impo | H23: rte | I23: ne | J23: to: | K23: Mone | L23: da: | M23: EUR | N23: Mon | O23: to: | P23: 0 | Q23: 15 | R23: 9075 | S23: {=- T} -> #NAME? | T23: asa actual Proporción - Opción 2 Importe bruto: Moneda: GBP Monto: 0.1814040396 - Tasa de referencia - Tasa de impuestos Importe neto: Moneda: GBP Monto: 0.1360530297 - Tasa de referencia
G24: 0.69 - Tasa actual - Porción de ingreso
G25: 0.157 - Tasa actual - Porción de ingreso Impo | H25: rte | I25: ne | J25: to: | K25: Mone | L25: da: | M25: GBP | N25: Mon | O25: to: | P25: 0 | Q25: 15 | R25: -7 | S25: Tasa | T25: actual Proporción - Opción 2
G26: 0.1 - Tasa actual - Tasa de impuestos Importe | H26: n | I26: eto: | J26: Mo | K26: neda: | L26: EU | M26: R Mo | N26: nto: | O26: 0 | P26: 65 | Q26: - | R26: Tas | S26: a ac | T26: tual
G27: 0.0237 - Tasa actual - Porción de ingreso
G28: 0.1062 - Tasa actual - Porción de ingreso
G29: 0.1934 - Tasa actual - Porción de ingreso
G30: 1.665327 - Tasa actual - Porción de ingreso
G31: 0.044 - Tasa actual - Porción de ingreso
G32: 0.360315 - Tasa actual - Porción de ingreso

Sheet Temp
D1: TRUE
